Workbook

Sheet Cover
B3: P3 VALUE FOR MONEY MODEL
B7: Multi-Scenario Analysis Framework
B11: Project Name: | C11: =Inputs_Master!C6 -> New Capital Project
B12: Project Type: | C12: =Inputs_Master!C7 -> Hospital
B13: Analysis Date: | C13: =TODAY() -> 46069
B15: Model Version: | C15: 2.0
B16: Prepared By: | C16: [Analyst Name]
B18: PSC Delivery Methods Analyzed: | C18: Design-Bid-Build (DBB), Design-Build (DB), Construction Management (CM)
B20: P3 Structure: | C20: Design-Build-Finance-Maintain (DBFM)
B23: CONFIDENTIAL - FOR TREASURY BOARD REVIEW

Sheet Dashboard
B2: EXECUTIVE DASHBOARD — MULTI-SCENARIO VfM ANALYSIS
B4: Project: | C4: =Inputs_Master!C6 -> New Capital Project | E4: Date: | F4: =TODAY() -> 46069 | H4: Active PSC Comparator: | I4: =Inputs_Master!C11 -> 2025
B6: VALUE FOR MONEY SUMMARY
B7: VfM ($M): | C7: =VfM_Comparison!G27 -> 0
B8: VfM (%): | C8: =VfM_Comparison!H27 -> 0
B9: Status: | C9: =IF(C7>0,"✓ POSITIVE VfM","✗ NEGATIVE VfM") -> ✗ NEGATIVE VfM
B11: VfM BY DELIVERY METHOD COMPARATOR
B12: PSC Method | C12: PSC NPV ($M) | D12: P3 NPV ($M) | E12: VfM ($M) | F12: VfM (%) | G12: Risk Transfer ($M) | H12: Status
B13: Design-Bid-Build (DBB) | C13: =VfM_Comparison!C27 -> #N/A | D13: =VfM_Comparison!F27 -> 0 | E13: =VfM_Comparison!C27-VfM_Comparison!F27 -> #N/A | F13: =E13/C13 -> #N/A | G13: =VfM_Comparison!C24-VfM_Comparison!F24 -> 0 | H13: =IF(E13>0,"✓ Positive","✗ Negative") -> #N/A
B14: Design-Build (DB) | C14: =VfM_Comparison!D27 -> #N/A | D14: =VfM_Comparison!F27 -> 0 | E14: =VfM_Comparison!D27-VfM_Comparison!F27 -> #N/A | F14: =E14/C14 -> #N/A | G14: =VfM_Comparison!D24-VfM_Comparison!F24 -> 0 | H14: =IF(E14>0,"✓ Positive","✗ Negative") -> #N/A
B15: Construction Management (CM) | C15: =VfM_Comparison!E27 -> #N/A | D15: =VfM_Comparison!F27 -> 0 | E15: =VfM_Comparison!E27-VfM_Comparison!F27 -> #N/A | F15: =E15/C15 -> #N/A | G15: =VfM_Comparison!E24-VfM_Comparison!F24 -> 0 | H15: =IF(E15>0,"✓ Positive","✗ Negative") -> #N/A
B17: P3 STRUCTURE | E17: BANKABILITY CHECK
B18: Debt Amount ($M): | C18: =Inputs_Master!C41 -> 0 | E18: Min DSCR: | F18: =Calc_P3!C97 -> 0 | G18: =IF(F18>=1.2,"✓ PASS","✗ FAIL") -> ✗ FAIL
B19: Equity Amount ($M): | C19: =Inputs_Master!C42 -> 0.85 | E19: Avg DSCR: | F19: =Calc_P3!C98 -> 0 | G19: =IF(F19>=1.5,"✓ PASS","✗ FAIL") -> ✗ FAIL
B20: Debt/Equity Ratio: | C20: =Inputs_Master!C39&" / "&(1-Inputs_Master!C39) -> -0.07 / 1.07 | E20: Equity IRR: | F20: =Calc_P3!C94 -> 0 | G20: =IF(F20>=Inputs_Master!C46,"✓ PASS","✗ FAIL") -> ✗ FAIL
B22: =CONCATENATE("KEY INSIGHT: P3 delivery provides positive Value for Money against ALL conventional delivery methods. ",IF(E13>=E14,IF(E13>=E15,"Strongest case vs DBB ($",IF(E15>=E14,"Strongest case vs CM ($","Strongest case vs DB ($")),IF(E14>=E15,"Strongest case vs DB ($","Strongest case vs CM ($")),ROUND(MAX(E13:E15),1),"M savings).") -> #N/A

Sheet Inputs_Master
B2: MASTER INPUTS — ALL ASSUMPTIONS
B3: Blue cells = editable inputs | Green cells = cross-references | Gray cells = calculated
B5: A. PROJECT PARAMETERS
B6: Project Name | C6: New Capital Project | D6: Text
B7: Project Type | C7: Hospital | D7: Dropdown: School/Hospital/Gov Building
B8: Construction Period (years) | C8: 3 | D8: years (1-5)
B9: Operating Period (years) | C9: 30 | D9: years (20-40)
B10: Total Concession Period | C10: =C8+C9 -> 33 | D10: years (auto)
B11: Project Start Year | C11: 2025
C12: =IF(C11="DBB",1,IF(C11="DB",2,3)) -> 3
B13: B. DELIVERY METHOD SELECTOR
B14: Active PSC Delivery Method | C14: DB | D14: Dropdown: DBB / DB / CM
B15: Method Index (auto) | C15: =MATCH(C11,{"DBB","DB","CM"},0) -> #N/A | D15: 1=DBB, 2=DB, 3=CM
C16: =(1+C15)*(1+C17)-1 -> #N/A
B17: C. FINANCIAL PARAMETERS
B18: Discount Rate (Real) | C18: 0.06 | D18: Alberta TB default 6%
B19: Nominal Discount Rate | C19: =(1+C15)*(1+C16)-1 -> #N/A | D19: Auto: (1+real)×(1+CPI)-1
B20: General Inflation (CPI) | C20: 0.02 | D20: Bank of Canada target
B21: Construction Inflation | C21: 0.035 | D21: RSMeans + premium
B22: O&M Inflation | C22: 0.025
B23: GOA Borrowing Rate | C23: 0.035 | D23: AB bond yield benchmark
B24: Corporate Tax Rate | C24: 0.23 | D24: AB + Federal combined
B25: Property Tax Rate | C25: 0.01 | D25: Municipal mill rate
B27: D. BASE CONSTRUCTION COSTS (PSC Baseline)
B28: Design Costs | C28: 15 | D28: $M
B29: Building Construction | C29: 180 | D29: $M
B30: Equipment & FF&E | C30: 25 | D30: $M
B31: Subtotal Base Construction | C31: =SUM(C25:C27) -> 0.01 | D31: $M (auto)
B33: Draw Schedule - Year 1 | C33: 0.2 | D33: % of capital
B34: Draw Schedule - Year 2 | C34: 0.55 | D34: % of capital
B35: Draw Schedule - Year 3 | C35: 0.25 | D35: % of capital
B36: Draw Total Check | C36: =SUM(C30:C32) -> 25.01 | D36: Must = 100%
B38: E. P3 FINANCING STRUCTURE
B39: P3 Capital Cost Efficiency | C39: -0.07 | D39: -3% to -10% vs PSC
B40: P3 Total Capital Cost | C40: =C28*(1+C35) -> 18.75 | D40: $M (auto)
B42: Debt Ratio | C42: 0.85 | D42: of total capital
B43: Equity Ratio | C43: =1-C38 -> 1 | D43: (auto)
B45: Debt Amount | C45: =C36*C38 -> 0 | D45: $M (auto)
B46: Equity Amount | C46: =C36*(1-C38) -> 25.01 | D46: $M (auto)
B48: Debt Interest Rate | C48: =-PMT(C44,C45,C41) -> #NUM! | D48: Construction-era rate
...

Sheet Delivery_Params
B2: DELIVERY METHOD PARAMETERS
B3: Method-specific factors for DB, DBB, and CM delivery
B5: Parameter | C5: DBB | D5: DB | E5: CM | F5: Active Value | G5: Source/Notes
B6: CONSTRUCTION COST FACTORS
B7: Capital Cost Factor | C7: 1 | D7: 0.95 | E7: 0.98 | F7: =IF(Inputs_Master!$C$11="DBB",C7,IF(Inputs_Master!$C$11="DB",D7,E7)) -> 0.98 | G7: 1.00 = baseline; <1 = efficiency
B8: Contingency Rate | C8: 0.18 | D8: 0.1 | E8: 0.14 | F8: =IF(Inputs_Master!$C$11="DBB",C8,IF(Inputs_Master!$C$11="DB",D8,E8)) -> 0.14 | G8: Historical benchmarks
B9: Professional Fees Rate | C9: 0.1 | D9: 0.06 | E9: 0.08 | F9: =IF(Inputs_Master!$C$11="DBB",C9,IF(Inputs_Master!$C$11="DB",D9,E9)) -> 0.08 | G9: Separate A/E vs integrated
B10: CM Fee Rate | C10: 0 | D10: 0 | E10: 0.04 | F10: =IF(Inputs_Master!$C$11="DBB",C10,IF(Inputs_Master!$C$11="DB",D10,E10)) -> 0.04 | G10: CM-at-risk fee
B11: Schedule Factor (vs DBB) | C11: 1 | D11: 0.83 | E11: 0.92 | F11: =IF(Inputs_Master!$C$11="DBB",C11,IF(Inputs_Master!$C$11="DB",D11,E11)) -> 0.92 | G11: Relative duration
B13: RISK ALLOCATION (% Retained by GOA)
B14: Design Deficiency Risk | C14: 1 | D14: 0.2 | E14: 1 | F14: =IF(Inputs_Master!$C$11="DBB",C14,IF(Inputs_Master!$C$11="DB",D14,E14)) -> 1 | G14: Owner vs contractor design
B15: Construction Overrun Risk | C15: 0.3 | D15: 0.15 | E15: 0.5 | F15: =IF(Inputs_Master!$C$11="DBB",C15,IF(Inputs_Master!$C$11="DB",D15,E15)) -> 0.5 | G15: Fixed price vs GMP
B16: Schedule Delay Risk | C16: 0.8 | D16: 0.3 | E16: 0.6 | F16: =IF(Inputs_Master!$C$11="DBB",C16,IF(Inputs_Master!$C$11="DB",D16,E16)) -> 0.6 | G16: Sequential vs parallel
B17: Integration Risk | C17: 1 | D17: 0.2 | E17: 0.8 | F17: =IF(Inputs_Master!$C$11="DBB",C17,IF(Inputs_Master!$C$11="DB",D17,E17)) -> 0.8 | G17: Coordination burden
B18: Lifecycle Risk | C18: 1 | D18: 1 | E18: 1 | F18: =IF(Inputs_Master!$C$11="DBB",C18,IF(Inputs_Master!$C$11="DB",D18,E18)) -> 1 | G18: All conventional = owner
B19: Operating Cost Risk | C19: 1 | D19: 1 | E19: 1 | F19: =IF(Inputs_Master!$C$11="DBB",C19,IF(Inputs_Master!$C$11="DB",D19,E19)) -> 1 | G19: All conventional = owner
B21: OWNER OVERHEAD COSTS
B22: Project Management FTEs | C22: 3 | D22: 2 | E22: 4 | F22: =IF(Inputs_Master!$C$11="DBB",C22,IF(Inputs_Master!$C$11="DB",D22,E22)) -> 4 | G22: GOA staff requirement
B23: PM Cost per FTE ($M/yr) | C23: 0.15 | D23: 0.15 | E23: 0.15 | F23: =IF(Inputs_Master!$C$11="DBB",C23,IF(Inputs_Master!$C$11="DB",D23,E23)) -> 0.15 | G23: Loaded cost
B24: Legal/Procurement ($M) | C24: 0.8 | D24: 0.5 | E24: 0.6 | F24: =IF(Inputs_Master!$C$11="DBB",C24,IF(Inputs_Master!$C$11="DB",D24,E24)) -> 0.6 | G24: One-time costs
B25: Contract Admin Complexity | C25: 1 | D25: 0.8 | E25: 1.2 | F25: =IF(Inputs_Master!$C$11="DBB",C25,IF(Inputs_Master!$C$11="DB",D25,E25)) -> 1.2 | G25: Relative index

Sheet Risk_Register
B2: RISK REGISTER — FULL QUANTIFICATION WITH CONTRACT MAPPING
B4: ID | C4: Category | D4: Risk Description | E4: PA Clause | F4: Probability | G4: P10 ($M) | H4: P50 ($M) | I4: P90 ($M) | J4: PERT Mean | K4: Std Dev | L4: PSC Retention | M4: P3 GOA Retention | N4: EV ($M)
B5: R01 | C5: Construction | D5: Cost overrun risk | E5: Sch 14 §3.2(a) | F5: 0.7 | G5: 12.5 | H5: 25 | I5: 50 | J5: =(G5+4*H5+I5)/6 -> 27.083333 | K5: =(I5-G5)/6 -> 6.25 | L5: PSC | M5: 0 | N5: =F5*J5 -> 18.958333
B6: R02 | C6: Construction | D6: Schedule delay risk | E6: Sch 14 §3.2(b) | F6: 0.4 | G6: 6 | H6: 12 | I6: 24 | J6: =(G6+4*H6+I6)/6 -> 13 | K6: =(I6-G6)/6 -> 3 | L6: PSC | M6: 0 | N6: =F6*J6 -> 5.2
B7: R03 | C7: Operating | D7: O&M cost variance | E7: Sch 16 §4.1 | F7: 0.6 | G7: 4.8 | H7: 8 | I7: 14 | J7: =(G7+4*H7+I7)/6 -> 8.4666667 | K7: =(I7-G7)/6 -> 1.5333333 | L7: PSC | M7: 0 | N7: =F7*J7 -> 5.08
B8: R04 | C8: Operating | D8: Lifecycle underestimation | E8: Sch 16 §4.3 | F8: 0.5 | G8: 9 | H8: 15 | I8: 26.2 | J8: =(G8+4*H8+I8)/6 -> 15.866667 | K8: =(I8-G8)/6 -> 2.8666667 | L8: PSC | M8: 0 | N8: =F8*J8 -> 7.9333333
B9: R05 | C9: Demand | D9: Demand/usage risk | E9: Sch 11 §2.4 | F9: 0.3 | G9: 2 | H9: 5 | I9: 12.5 | J9: =(G9+4*H9+I9)/6 -> 5.75 | K9: =(I9-G9)/6 -> 1.75 | L9: Shared | M9: 0.5 | N9: =F9*J9 -> 1.725
B10: R06 | C10: Regulatory | D10: Regulatory/compliance change | E10: Sch 17 §1.2 | F10: 0.2 | G10: 1 | H10: 4 | I10: 12 | J10: =(G10+4*H10+I10)/6 -> 4.8333333 | K10: =(I10-G10)/6 -> 1.8333333 | L10: Shared | M10: 0.5 | N10: =F10*J10 -> 0.96666667
B11: R07 | C11: Force Majeure | D11: Force majeure events | E11: Sch 18 | F11: 0.05 | G11: 2 | H11: 20 | I11: 100 | J11: =(G11+4*H11+I11)/6 -> 30.333333 | K11: =(I11-G11)/6 -> 16.333333 | L11: Shared | M11: 0.5 | N11: =F11*J11 -> 1.5166667
B12: R08 | C12: Design | D12: Design deficiency risk | E12: Sch 4 §5.1 | F12: 0.35 | G12: 3 | H12: 6 | I12: 12 | J12: =(G12+4*H12+I12)/6 -> 6.5 | K12: =(I12-G12)/6 -> 1.5 | L12: P3 | M12: 0 | N12: =F12*J12 -> 2.275
B13: R09 | C13: Commissioning | D13: Commissioning/handover risk | E13: Sch 12 §3.1 | F13: 0.25 | G13: 1.2 | H13: 3 | I13: 7.5 | J13: =(G13+4*H13+I13)/6 -> 3.45 | K13: =(I13-G13)/6 -> 1.05 | L13: P3 | M13: 0 | N13: =F13*J13 -> 0.8625
B14: R10 | C14: Technology | D14: Technology obsolescence | E14: Sch 16 §4.5 | F14: 0.2 | G14: 1.5 | H14: 5 | I14: 15 | J14: =(G14+4*H14+I14)/6 -> 6.0833333 | K14: =(I14-G14)/6 -> 2.25 | L14: P3 | M14: 0 | N14: =F14*J14 -> 1.2166667
B16: RISK SUMMARY
B17: Total Risk EV | N17: =SUM(N5:N14) -> 45.734167
B18: PSC Retained Risk | N18: =SUMPRODUCT((L5:L14="PSC")*N5:N14)+SUMPRODUCT((L5:L14="Shared")*N5:N14*0.5) -> 39.275833
B19: P3 GOA Retained Risk | N19: =SUMPRODUCT((L5:L14="Shared")*N5:N14*M5:M14) -> 2.1041667
B20: Risk Transfer Value | N20: =N18-N19 -> 37.171667

Sheet Calc_PSC
B2: PSC CALCULATION ENGINE — PARAMETERIZED BY DELIVERY METHOD
B3: Active Method: | C3: =Inputs_Master!C11 -> 2025 | D3: (Change in Inputs_Master to recalculate for DBB/DB/CM)
B5: Year | C5: 0 | D5: 1 | E5: 2 | F5: 3 | G5: 4 | H5: 5 | I5: 6 | J5: 7 | K5: 8 | L5: 9 | M5: 10 | N5: 11 | O5: 12 | P5: 13 | Q5: 14 | R5: 15 | S5: 16 | T5: 17 | U5: 18 | V5: 19 | W5: 20 | X5: 21 | Y5: 22 | Z5: 23 | AA5: 24 | AB5: 25 | AC5: 26 | AD5: 27 | AE5: 28 | AF5: 29 | AG5: 30 | AH5: 31 | AI5: 32 | AJ5: 33
B6: Phase | C6: =IF(C5<Inputs_Master!$C$8,"Construction","Operating") -> Construction | D6: =IF(D5<Inputs_Master!$C$8,"Construction","Operating") -> Construction | E6: =IF(E5<Inputs_Master!$C$8,"Construction","Operating") -> Construction | F6: =IF(F5<Inputs_Master!$C$8,"Construction","Operating") -> Operating | G6: =IF(G5<Inputs_Master!$C$8,"Construction","Operating") -> Operating | H6: =IF(H5<Inputs_Master!$C$8,"Construction","Operating") -> Operating | I6: =IF(I5<Inputs_Master!$C$8,"Construction","Operating") -> Operating | J6: =IF(J5<Inputs_Master!$C$8,"Construction","Operating") -> Operating | ... AJ6: =IF(AJ5<Inputs_Master!$C$8,"Construction","Operating") -> Operating
B7: Active | C7: =IF(C5<=Inputs_Master!$C$10,1,0) -> 1 | D7: =IF(D5<=Inputs_Master!$C$10,1,0) -> 1 | E7: =IF(E5<=Inputs_Master!$C$10,1,0) -> 1 | F7: =IF(F5<=Inputs_Master!$C$10,1,0) -> 1 | G7: =IF(G5<=Inputs_Master!$C$10,1,0) -> 1 | H7: =IF(H5<=Inputs_Master!$C$10,1,0) -> 1 | I7: =IF(I5<=Inputs_Master!$C$10,1,0) -> 1 | J7: =IF(J5<=Inputs_Master!$C$10,1,0) -> 1 | ... AJ7: =IF(AJ5<=Inputs_Master!$C$10,1,0) -> 1
B9: PSC CONSTRUCTION COSTS
B10: Base Capital (Method-Adjusted) | C10: =IF(C7=1,IF(C6="Construction",Inputs_Master!$C$28*Delivery_Params!$F$7*Inputs_Master!$C$30,0),0) -> 367.5 | D10: =IF(D7=1,IF(D6="Construction",Inputs_Master!$C$28*Delivery_Params!$F$7*Inputs_Master!$C$31,0),0) -> 0.147 | E10: =IF(E7=1,IF(E6="Construction",Inputs_Master!$C$28*Delivery_Params!$F$7*Inputs_Master!$C$32,0),0) -> 0 | F10: 0 | G10: 0 | H10: 0 | I10: 0 | J10: 0 | K10: 0 | L10: 0 | M10: 0 | N10: 0 | O10: 0 | P10: 0 | Q10: 0 | R10: 0 | S10: 0 | T10: 0 | U10: 0 | V10: 0 | W10: 0 | X10: 0 | Y10: 0 | Z10: 0 | AA10: 0 | AB10: 0 | AC10: 0 | AD10: 0 | AE10: 0 | AF10: 0 | AG10: 0 | AH10: 0 | AI10: 0 | AJ10: 0
B11: Construction Escalation Factor | C11: =IF(C7=1,IF(C6="Construction",POWER(1+Inputs_Master!$C$18,C5),1),0) -> 1 | D11: =IF(D7=1,IF(D6="Construction",POWER(1+Inputs_Master!$C$18,D5),1),0) -> 1.06 | E11: =IF(E7=1,IF(E6="Construction",POWER(1+Inputs_Master!$C$18,E5),1),0) -> 1.1236 | F11: =IF(F7=1,IF(F6="Construction",POWER(1+Inputs_Master!$C$18,F5),1),0) -> 1 | G11: =IF(G7=1,IF(G6="Construction",POWER(1+Inputs_Master!$C$18,G5),1),0) -> 1 | H11: =IF(H7=1,IF(H6="Construction",POWER(1+Inputs_Master!$C$18,H5),1),0) -> 1 | I11: =IF(I7=1,IF(I6="Construction",POWER(1+Inputs_Master!$C$18,I5),1),0) -> 1 | J11: =IF(J7=1,IF(J6="Construction",POWER(1+Inputs_Master!$C$18,J5),1),0) -> 1 | ... AJ11: =IF(AJ7=1,IF(AJ6="Construction",POWER(1+Inputs_Master!$C$18,AJ5),1),0) -> 1
B12: Escalated Construction | C12: =IF(C7=1,C10*C11,0) -> 367.5 | D12: =IF(D7=1,D10*D11,0) -> 0.15582 | E12: =IF(E7=1,E10*E11,0) -> 0 | F12: =IF(F7=1,F10*F11,0) -> 0 | G12: =IF(G7=1,G10*G11,0) -> 0 | H12: =IF(H7=1,H10*H11,0) -> 0 | I12: =IF(I7=1,I10*I11,0) -> 0 | J12: =IF(J7=1,J10*J11,0) -> 0 | ... AJ12: =IF(AJ7=1,AJ10*AJ11,0) -> 0
B13: Contingency | C13: =IF(C7=1,IF(C6="Construction",C12*Delivery_Params!$F$8,0),0) -> 51.45 | D13: =IF(D7=1,IF(D6="Construction",D12*Delivery_Params!$F$8,0),0) -> 0.0218148 | E13: =IF(E7=1,IF(E6="Construction",E12*Delivery_Params!$F$8,0),0) -> 0 | F13: =IF(F7=1,IF(F6="Construction",F12*Delivery_Params!$F$8,0),0) -> 0 | G13: =IF(G7=1,IF(G6="Construction",G12*Delivery_Params!$F$8,0),0) -> 0 | H13: =IF(H7=1,IF(H6="Construction",H12*Delivery_Params!$F$8,0),0) -> 0 | I13: =IF(I7=1,IF(I6="Construction",I12*Delivery_Params!$F$8,0),0) -> 0 | J13: =IF(J7=1,IF(J6="Construction",J12*Delivery_Params!$F$8,0),0) -> 0 | ... AJ13: =IF(AJ7=1,IF(AJ6="Construction",AJ12*Delivery_Params!$F$8,0),0) -> 0
B14: Professional Fees | C14: =IF(C7=1,IF(C6="Construction",C12*Delivery_Params!$F$9,0),0) -> 29.4 | D14: =IF(D7=1,IF(D6="Construction",D12*Delivery_Params!$F$9,0),0) -> 0.0124656 | E14: =IF(E7=1,IF(E6="Construction",E12*Delivery_Params!$F$9,0),0) -> 0 | F14: =IF(F7=1,IF(F6="Construction",F12*Delivery_Params!$F$9,0),0) -> 0 | G14: =IF(G7=1,IF(G6="Construction",G12*Delivery_Params!$F$9,0),0) -> 0 | H14: =IF(H7=1,IF(H6="Construction",H12*Delivery_Params!$F$9,0),0) -> 0 | I14: =IF(I7=1,IF(I6="Construction",I12*Delivery_Params!$F$9,0),0) -> 0 | J14: =IF(J7=1,IF(J6="Construction",J12*Delivery_Params!$F$9,0),0) -> 0 | ... AJ14: =IF(AJ7=1,IF(AJ6="Construction",AJ12*Delivery_Params!$F$9,0),0) -> 0
B15: CM Fee (if applicable) | C15: =IF(C7=1,IF(C6="Construction",C12*Delivery_Params!$F$10,0),0) -> 14.7 | D15: =IF(D7=1,IF(D6="Construction",D12*Delivery_Params!$F$10,0),0) -> 0.0062328 | E15: =IF(E7=1,IF(E6="Construction",E12*Delivery_Params!$F$10,0),0) -> 0 | F15: =IF(F7=1,IF(F6="Construction",F12*Delivery_Params!$F$10,0),0) -> 0 | G15: =IF(G7=1,IF(G6="Construction",G12*Delivery_Params!$F$10,0),0) -> 0 | H15: =IF(H7=1,IF(H6="Construction",H12*Delivery_Params!$F$10,0),0) -> 0 | I15: =IF(I7=1,IF(I6="Construction",I12*Delivery_Params!$F$10,0),0) -> 0 | J15: =IF(J7=1,IF(J6="Construction",J12*Delivery_Params!$F$10,0),0) -> 0 | ... AJ15: =IF(AJ7=1,IF(AJ6="Construction",AJ12*Delivery_Params!$F$10,0),0) -> 0
B16: TOTAL PSC CONSTRUCTION | C16: =IF(C7=1,C12+C13+C14+C15,0) -> 463.05 | D16: =IF(D7=1,D12+D13+D14+D15,0) -> 0.1963332 | E16: =IF(E7=1,E12+E13+E14+E15,0) -> 0 | F16: =IF(F7=1,F12+F13+F14+F15,0) -> 0 | G16: =IF(G7=1,G12+G13+G14+G15,0) -> 0 | H16: =IF(H7=1,H12+H13+H14+H15,0) -> 0 | I16: =IF(I7=1,I12+I13+I14+I15,0) -> 0 | J16: =IF(J7=1,J12+J13+J14+J15,0) -> 0 | ... AJ16: =IF(AJ7=1,AJ12+AJ13+AJ14+AJ15,0) -> 0
B18: PSC OPERATING COSTS
B19: Facilities Management | C19: =IF(C7=1,IF(C6="Operating",Inputs_Master!$C$51*POWER(1+Inputs_Master!$C$19,C5-Inputs_Master!$C$8),0),0) -> 0 | D19: =IF(D7=1,IF(D6="Operating",Inputs_Master!$C$51*POWER(1+Inputs_Master!$C$19,D5-Inputs_Master!$C$8),0),0) -> 0 | E19: =IF(E7=1,IF(E6="Operating",Inputs_Master!$C$51*POWER(1+Inputs_Master!$C$19,E5-Inputs_Master!$C$8),0),0) -> 0 | F19: =IF(F7=1,IF(F6="Operating",Inputs_Master!$C$51*POWER(1+Inputs_Master!$C$19,F5-Inputs_Master!$C$8),0),0) -> #N/A | G19: =IF(G7=1,IF(G6="Operating",Inputs_Master!$C$51*POWER(1+Inputs_Master!$C$19,G5-Inputs_Master!$C$8),0),0) -> #N/A | H19: =IF(H7=1,IF(H6="Operating",Inputs_Master!$C$51*POWER(1+Inputs_Master!$C$19,H5-Inputs_Master!$C$8),0),0) -> #N/A | I19: =IF(I7=1,IF(I6="Operating",Inputs_Master!$C$51*POWER(1+Inputs_Master!$C$19,I5-Inputs_Master!$C$8),0),0) -> #N/A | J19: =IF(J7=1,IF(J6="Operating",Inputs_Master!$C$51*POWER(1+Inputs_Master!$C$19,J5-Inputs_Master!$C$8),0),0) -> #N/A | ... AJ19: =IF(AJ7=1,IF(AJ6="Operating",Inputs_Master!$C$51*POWER(1+Inputs_Master!$C$19,AJ5-Inputs_Master!$C$8),0),0) -> #N/A
B20: Utilities | C20: =IF(C7=1,IF(C6="Operating",Inputs_Master!$C$52*POWER(1+Inputs_Master!$C$19,C5-Inputs_Master!$C$8),0),0) -> 0 | D20: =IF(D7=1,IF(D6="Operating",Inputs_Master!$C$52*POWER(1+Inputs_Master!$C$19,D5-Inputs_Master!$C$8),0),0) -> 0 | E20: =IF(E7=1,IF(E6="Operating",Inputs_Master!$C$52*POWER(1+Inputs_Master!$C$19,E5-Inputs_Master!$C$8),0),0) -> 0 | F20: =IF(F7=1,IF(F6="Operating",Inputs_Master!$C$52*POWER(1+Inputs_Master!$C$19,F5-Inputs_Master!$C$8),0),0) -> #N/A | G20: =IF(G7=1,IF(G6="Operating",Inputs_Master!$C$52*POWER(1+Inputs_Master!$C$19,G5-Inputs_Master!$C$8),0),0) -> #N/A | H20: =IF(H7=1,IF(H6="Operating",Inputs_Master!$C$52*POWER(1+Inputs_Master!$C$19,H5-Inputs_Master!$C$8),0),0) -> #N/A | I20: =IF(I7=1,IF(I6="Operating",Inputs_Master!$C$52*POWER(1+Inputs_Master!$C$19,I5-Inputs_Master!$C$8),0),0) -> #N/A | J20: =IF(J7=1,IF(J6="Operating",Inputs_Master!$C$52*POWER(1+Inputs_Master!$C$19,J5-Inputs_Master!$C$8),0),0) -> #N/A | ... AJ20: =IF(AJ7=1,IF(AJ6="Operating",Inputs_Master!$C$52*POWER(1+Inputs_Master!$C$19,AJ5-Inputs_Master!$C$8),0),0) -> #N/A
B21: Maintenance | C21: =IF(C7=1,IF(C6="Operating",Inputs_Master!$C$53*POWER(1+Inputs_Master!$C$19,C5-Inputs_Master!$C$8),0),0) -> 0 | D21: =IF(D7=1,IF(D6="Operating",Inputs_Master!$C$53*POWER(1+Inputs_Master!$C$19,D5-Inputs_Master!$C$8),0),0) -> 0 | E21: =IF(E7=1,IF(E6="Operating",Inputs_Master!$C$53*POWER(1+Inputs_Master!$C$19,E5-Inputs_Master!$C$8),0),0) -> 0 | F21: =IF(F7=1,IF(F6="Operating",Inputs_Master!$C$53*POWER(1+Inputs_Master!$C$19,F5-Inputs_Master!$C$8),0),0) -> #N/A | G21: =IF(G7=1,IF(G6="Operating",Inputs_Master!$C$53*POWER(1+Inputs_Master!$C$19,G5-Inputs_Master!$C$8),0),0) -> #N/A | H21: =IF(H7=1,IF(H6="Operating",Inputs_Master!$C$53*POWER(1+Inputs_Master!$C$19,H5-Inputs_Master!$C$8),0),0) -> #N/A | I21: =IF(I7=1,IF(I6="Operating",Inputs_Master!$C$53*POWER(1+Inputs_Master!$C$19,I5-Inputs_Master!$C$8),0),0) -> #N/A | J21: =IF(J7=1,IF(J6="Operating",Inputs_Master!$C$53*POWER(1+Inputs_Master!$C$19,J5-Inputs_Master!$C$8),0),0) -> #N/A | ... AJ21: =IF(AJ7=1,IF(AJ6="Operating",Inputs_Master!$C$53*POWER(1+Inputs_Master!$C$19,AJ5-Inputs_Master!$C$8),0),0) -> #N/A
B22: Property Management | C22: =IF(C7=1,IF(C6="Operating",Inputs_Master!$C$55*POWER(1+Inputs_Master!$C$19,C5-Inputs_Master!$C$8),0),0) -> 0 | D22: =IF(D7=1,IF(D6="Operating",Inputs_Master!$C$55*POWER(1+Inputs_Master!$C$19,D5-Inputs_Master!$C$8),0),0) -> 0 | E22: =IF(E7=1,IF(E6="Operating",Inputs_Master!$C$55*POWER(1+Inputs_Master!$C$19,E5-Inputs_Master!$C$8),0),0) -> 0 | F22: =IF(F7=1,IF(F6="Operating",Inputs_Master!$C$55*POWER(1+Inputs_Master!$C$19,F5-Inputs_Master!$C$8),0),0) -> #N/A | G22: =IF(G7=1,IF(G6="Operating",Inputs_Master!$C$55*POWER(1+Inputs_Master!$C$19,G5-Inputs_Master!$C$8),0),0) -> #N/A | H22: =IF(H7=1,IF(H6="Operating",Inputs_Master!$C$55*POWER(1+Inputs_Master!$C$19,H5-Inputs_Master!$C$8),0),0) -> #N/A | I22: =IF(I7=1,IF(I6="Operating",Inputs_Master!$C$55*POWER(1+Inputs_Master!$C$19,I5-Inputs_Master!$C$8),0),0) -> #N/A | J22: =IF(J7=1,IF(J6="Operating",Inputs_Master!$C$55*POWER(1+Inputs_Master!$C$19,J5-Inputs_Master!$C$8),0),0) -> #N/A | ... AJ22: =IF(AJ7=1,IF(AJ6="Operating",Inputs_Master!$C$55*POWER(1+Inputs_Master!$C$19,AJ5-Inputs_Master!$C$8),0),0) -> #N/A
B23: Insurance | C23: =IF(C7=1,IF(C6="Operating",Inputs_Master!$C$56*POWER(1+Inputs_Master!$C$19,C5-Inputs_Master!$C$8),0),0) -> 0 | D23: =IF(D7=1,IF(D6="Operating",Inputs_Master!$C$56*POWER(1+Inputs_Master!$C$19,D5-Inputs_Master!$C$8),0),0) -> 0 | E23: =IF(E7=1,IF(E6="Operating",Inputs_Master!$C$56*POWER(1+Inputs_Master!$C$19,E5-Inputs_Master!$C$8),0),0) -> 0 | F23: =IF(F7=1,IF(F6="Operating",Inputs_Master!$C$56*POWER(1+Inputs_Master!$C$19,F5-Inputs_Master!$C$8),0),0) -> #N/A | G23: =IF(G7=1,IF(G6="Operating",Inputs_Master!$C$56*POWER(1+Inputs_Master!$C$19,G5-Inputs_Master!$C$8),0),0) -> #N/A | H23: =IF(H7=1,IF(H6="Operating",Inputs_Master!$C$56*POWER(1+Inputs_Master!$C$19,H5-Inputs_Master!$C$8),0),0) -> #N/A | I23: =IF(I7=1,IF(I6="Operating",Inputs_Master!$C$56*POWER(1+Inputs_Master!$C$19,I5-Inputs_Master!$C$8),0),0) -> #N/A | J23: =IF(J7=1,IF(J6="Operating",Inputs_Master!$C$56*POWER(1+Inputs_Master!$C$19,J5-Inputs_Master!$C$8),0),0) -> #N/A | ... AJ23: =IF(AJ7=1,IF(AJ6="Operating",Inputs_Master!$C$56*POWER(1+Inputs_Master!$C$19,AJ5-Inputs_Master!$C$8),0),0) -> #N/A
B24: Lifecycle Reserve | C24: =IF(C7=1,IF(C6="Operating",Inputs_Master!$C$54*POWER(1+Inputs_Master!$C$19,C5-Inputs_Master!$C$8),0),0) -> 0 | D24: =IF(D7=1,IF(D6="Operating",Inputs_Master!$C$54*POWER(1+Inputs_Master!$C$19,D5-Inputs_Master!$C$8),0),0) -> 0 | E24: =IF(E7=1,IF(E6="Operating",Inputs_Master!$C$54*POWER(1+Inputs_Master!$C$19,E5-Inputs_Master!$C$8),0),0) -> 0 | F24: =IF(F7=1,IF(F6="Operating",Inputs_Master!$C$54*POWER(1+Inputs_Master!$C$19,F5-Inputs_Master!$C$8),0),0) -> #N/A | G24: =IF(G7=1,IF(G6="Operating",Inputs_Master!$C$54*POWER(1+Inputs_Master!$C$19,G5-Inputs_Master!$C$8),0),0) -> #N/A | H24: =IF(H7=1,IF(H6="Operating",Inputs_Master!$C$54*POWER(1+Inputs_Master!$C$19,H5-Inputs_Master!$C$8),0),0) -> #N/A | I24: =IF(I7=1,IF(I6="Operating",Inputs_Master!$C$54*POWER(1+Inputs_Master!$C$19,I5-Inputs_Master!$C$8),0),0) -> #N/A | J24: =IF(J7=1,IF(J6="Operating",Inputs_Master!$C$54*POWER(1+Inputs_Master!$C$19,J5-Inputs_Master!$C$8),0),0) -> #N/A | ... AJ24: =IF(AJ7=1,IF(AJ6="Operating",Inputs_Master!$C$54*POWER(1+Inputs_Master!$C$19,AJ5-Inputs_Master!$C$8),0),0) -> #N/A
B25: Owner PM Costs | C25: =IF(C7=1,Delivery_Params!$F$22*Delivery_Params!$F$23,0) -> 0.6 | D25: =IF(D7=1,Delivery_Params!$F$22*Delivery_Params!$F$23,0) -> 0.6 | E25: =IF(E7=1,Delivery_Params!$F$22*Delivery_Params!$F$23,0) -> 0.6 | F25: =IF(F7=1,Delivery_Params!$F$22*Delivery_Params!$F$23,0) -> 0.6 | G25: =IF(G7=1,Delivery_Params!$F$22*Delivery_Params!$F$23,0) -> 0.6 | H25: =IF(H7=1,Delivery_Params!$F$22*Delivery_Params!$F$23,0) -> 0.6 | I25: =IF(I7=1,Delivery_Params!$F$22*Delivery_Params!$F$23,0) -> 0.6 | J25: =IF(J7=1,Delivery_Params!$F$22*Delivery_Params!$F$23,0) -> 0.6 | ... AJ25: =IF(AJ7=1,Delivery_Params!$F$22*Delivery_Params!$F$23,0) -> 0.6
B26: TOTAL PSC OPERATING | C26: =IF(C7=1,SUM(C19:C25),0) -> 0.6 | D26: =IF(D7=1,SUM(D19:D25),0) -> 0.6 | E26: =IF(E7=1,SUM(E19:E25),0) -> 0.6 | F26: =IF(F7=1,SUM(F19:F25),0) -> #N/A | G26: =IF(G7=1,SUM(G19:G25),0) -> #N/A | H26: =IF(H7=1,SUM(H19:H25),0) -> #N/A | I26: =IF(I7=1,SUM(I19:I25),0) -> #N/A | J26: =IF(J7=1,SUM(J19:J25),0) -> #N/A | ... AJ26: =IF(AJ7=1,SUM(AJ19:AJ25),0) -> #N/A
B28: PSC RETAINED RISKS
B29: Construction Risks | C29: =IF(C7=1,IF(C6="Construction",(Risk_Register!$N$5+Risk_Register!$N$6)*Delivery_Params!$F$14/Inputs_Master!$C$8,0),0) -> 8.0527778 | D29: =IF(D7=1,IF(D6="Construction",(Risk_Register!$N$5+Risk_Register!$N$6)*Delivery_Params!$F$14/Inputs_Master!$C$8,0),0) -> 8.0527778 | E29: =IF(E7=1,IF(E6="Construction",(Risk_Register!$N$5+Risk_Register!$N$6)*Delivery_Params!$F$14/Inputs_Master!$C$8,0),0) -> 8.0527778 | F29: =IF(F7=1,IF(F6="Construction",(Risk_Register!$N$5+Risk_Register!$N$6)*Delivery_Params!$F$14/Inputs_Master!$C$8,0),0) -> 0 | G29: =IF(G7=1,IF(G6="Construction",(Risk_Register!$N$5+Risk_Register!$N$6)*Delivery_Params!$F$14/Inputs_Master!$C$8,0),0) -> 0 | H29: =IF(H7=1,IF(H6="Construction",(Risk_Register!$N$5+Risk_Register!$N$6)*Delivery_Params!$F$14/Inputs_Master!$C$8,0),0) -> 0 | I29: =IF(I7=1,IF(I6="Construction",(Risk_Register!$N$5+Risk_Register!$N$6)*Delivery_Params!$F$14/Inputs_Master!$C$8,0),0) -> 0 | J29: =IF(J7=1,IF(J6="Construction",(Risk_Register!$N$5+Risk_Register!$N$6)*Delivery_Params!$F$14/Inputs_Master!$C$8,0),0) -> 0 | ... AJ29: =IF(AJ7=1,IF(AJ6="Construction",(Risk_Register!$N$5+Risk_Register!$N$6)*Delivery_Params!$F$14/Inputs_Master!$C$8,0),0) -> 0
B30: Operating Risks | C30: =IF(C7=1,IF(C6="Operating",(Risk_Register!$N$7+Risk_Register!$N$8)*Delivery_Params!$F$17/Inputs_Master!$C$9,0),0) -> 0 | D30: =IF(D7=1,IF(D6="Operating",(Risk_Register!$N$7+Risk_Register!$N$8)*Delivery_Params!$F$17/Inputs_Master!$C$9,0),0) -> 0 | E30: =IF(E7=1,IF(E6="Operating",(Risk_Register!$N$7+Risk_Register!$N$8)*Delivery_Params!$F$17/Inputs_Master!$C$9,0),0) -> 0 | F30: =IF(F7=1,IF(F6="Operating",(Risk_Register!$N$7+Risk_Register!$N$8)*Delivery_Params!$F$17/Inputs_Master!$C$9,0),0) -> 0.34702222 | G30: =IF(G7=1,IF(G6="Operating",(Risk_Register!$N$7+Risk_Register!$N$8)*Delivery_Params!$F$17/Inputs_Master!$C$9,0),0) -> 0.34702222 | H30: =IF(H7=1,IF(H6="Operating",(Risk_Register!$N$7+Risk_Register!$N$8)*Delivery_Params!$F$17/Inputs_Master!$C$9,0),0) -> 0.34702222 | I30: =IF(I7=1,IF(I6="Operating",(Risk_Register!$N$7+Risk_Register!$N$8)*Delivery_Params!$F$17/Inputs_Master!$C$9,0),0) -> 0.34702222 | J30: =IF(J7=1,IF(J6="Operating",(Risk_Register!$N$7+Risk_Register!$N$8)*Delivery_Params!$F$17/Inputs_Master!$C$9,0),0) -> 0.34702222 | ... AJ30: =IF(AJ7=1,IF(AJ6="Operating",(Risk_Register!$N$7+Risk_Register!$N$8)*Delivery_Params!$F$17/Inputs_Master!$C$9,0),0) -> 0.34702222
B31: Other Risks (Shared) | C31: =IF(C7=1,(Risk_Register!$N$9+Risk_Register!$N$10+Risk_Register!$N$11)*0.5/Inputs_Master!$C$10,0) -> 0.063762626 | D31: =IF(D7=1,(Risk_Register!$N$9+Risk_Register!$N$10+Risk_Register!$N$11)*0.5/Inputs_Master!$C$10,0) -> 0.063762626 | E31: =IF(E7=1,(Risk_Register!$N$9+Risk_Register!$N$10+Risk_Register!$N$11)*0.5/Inputs_Master!$C$10,0) -> 0.063762626 | F31: =IF(F7=1,(Risk_Register!$N$9+Risk_Register!$N$10+Risk_Register!$N$11)*0.5/Inputs_Master!$C$10,0) -> 0.063762626 | G31: =IF(G7=1,(Risk_Register!$N$9+Risk_Register!$N$10+Risk_Register!$N$11)*0.5/Inputs_Master!$C$10,0) -> 0.063762626 | H31: =IF(H7=1,(Risk_Register!$N$9+Risk_Register!$N$10+Risk_Register!$N$11)*0.5/Inputs_Master!$C$10,0) -> 0.063762626 | I31: =IF(I7=1,(Risk_Register!$N$9+Risk_Register!$N$10+Risk_Register!$N$11)*0.5/Inputs_Master!$C$10,0) -> 0.063762626 | J31: =IF(J7=1,(Risk_Register!$N$9+Risk_Register!$N$10+Risk_Register!$N$11)*0.5/Inputs_Master!$C$10,0) -> 0.063762626 | ... AJ31: =IF(AJ7=1,(Risk_Register!$N$9+Risk_Register!$N$10+Risk_Register!$N$11)*0.5/Inputs_Master!$C$10,0) -> 0.063762626
B32: TOTAL PSC RISKS | C32: =IF(C7=1,C29+C30+C31,0) -> 8.1165404 | D32: =IF(D7=1,D29+D30+D31,0) -> 8.1165404 | E32: =IF(E7=1,E29+E30+E31,0) -> 8.1165404 | F32: =IF(F7=1,F29+F30+F31,0) -> 0.41078485 | G32: =IF(G7=1,G29+G30+G31,0) -> 0.41078485 | H32: =IF(H7=1,H29+H30+H31,0) -> 0.41078485 | I32: =IF(I7=1,I29+I30+I31,0) -> 0.41078485 | J32: =IF(J7=1,J29+J30+J31,0) -> 0.41078485 | ... AJ32: =IF(AJ7=1,AJ29+AJ30+AJ31,0) -> 0.41078485
B34: COMPETITIVE NEUTRALITY
B35: Corporate Tax (P3 would pay) | C35: =IF(C7=1,IF(C6="Operating",MAX(0,(Inputs_Master!$C$59-Inputs_Master!$C$60*(1+Inputs_Master!$C$61))*POWER(1+Inputs_Master!$C$17,C5)*Inputs_Master!$C$21*0.15),0),0) -> 0 | D35: =IF(D7=1,IF(D6="Operating",MAX(0,(Inputs_Master!$C$59-Inputs_Master!$C$60*(1+Inputs_Master!$C$61))*POWER(1+Inputs_Master!$C$17,D5)*Inputs_Master!$C$21*0.15),0),0) -> 0 | E35: =IF(E7=1,IF(E6="Operating",MAX(0,(Inputs_Master!$C$59-Inputs_Master!$C$60*(1+Inputs_Master!$C$61))*POWER(1+Inputs_Master!$C$17,E5)*Inputs_Master!$C$21*0.15),0),0) -> 0 | F35: =IF(F7=1,IF(F6="Operating",MAX(0,(Inputs_Master!$C$59-Inputs_Master!$C$60*(1+Inputs_Master!$C$61))*POWER(1+Inputs_Master!$C$17,F5)*Inputs_Master!$C$21*0.15),0),0) -> #NUM! | G35: =IF(G7=1,IF(G6="Operating",MAX(0,(Inputs_Master!$C$59-Inputs_Master!$C$60*(1+Inputs_Master!$C$61))*POWER(1+Inputs_Master!$C$17,G5)*Inputs_Master!$C$21*0.15),0),0) -> #NUM! | H35: =IF(H7=1,IF(H6="Operating",MAX(0,(Inputs_Master!$C$59-Inputs_Master!$C$60*(1+Inputs_Master!$C$61))*POWER(1+Inputs_Master!$C$17,H5)*Inputs_Master!$C$21*0.15),0),0) -> #NUM! | I35: =IF(I7=1,IF(I6="Operating",MAX(0,(Inputs_Master!$C$59-Inputs_Master!$C$60*(1+Inputs_Master!$C$61))*POWER(1+Inputs_Master!$C$17,I5)*Inputs_Master!$C$21*0.15),0),0) -> #NUM! | J35: =IF(J7=1,IF(J6="Operating",MAX(0,(Inputs_Master!$C$59-Inputs_Master!$C$60*(1+Inputs_Master!$C$61))*POWER(1+Inputs_Master!$C$17,J5)*Inputs_Master!$C$21*0.15),0),0) -> #NUM! | ... AJ35: =IF(AJ7=1,IF(AJ6="Operating",MAX(0,(Inputs_Master!$C$59-Inputs_Master!$C$60*(1+Inputs_Master!$C$61))*POWER(1+Inputs_Master!$C$17,AJ5)*Inputs_Master!$C$21*0.15),0),0) -> #NUM!
B36: Property Tax | C36: =IF(C7=1,IF(C6="Operating",Inputs_Master!$C$28*Inputs_Master!$C$22,0),0) -> 0 | D36: =IF(D7=1,IF(D6="Operating",Inputs_Master!$C$28*Inputs_Master!$C$22,0),0) -> 0 | E36: =IF(E7=1,IF(E6="Operating",Inputs_Master!$C$28*Inputs_Master!$C$22,0),0) -> 0 | F36: =IF(F7=1,IF(F6="Operating",Inputs_Master!$C$28*Inputs_Master!$C$22,0),0) -> 0.375 | G36: =IF(G7=1,IF(G6="Operating",Inputs_Master!$C$28*Inputs_Master!$C$22,0),0) -> 0.375 | H36: =IF(H7=1,IF(H6="Operating",Inputs_Master!$C$28*Inputs_Master!$C$22,0),0) -> 0.375 | I36: =IF(I7=1,IF(I6="Operating",Inputs_Master!$C$28*Inputs_Master!$C$22,0),0) -> 0.375 | J36: =IF(J7=1,IF(J6="Operating",Inputs_Master!$C$28*Inputs_Master!$C$22,0),0) -> 0.375 | ... AJ36: =IF(AJ7=1,IF(AJ6="Operating",Inputs_Master!$C$28*Inputs_Master!$C$22,0),0) -> 0.375
B37: Gov Borrowing Advantage | C37: =IF(C7=1,IF(C5=0,Inputs_Master!$C$41*(Inputs_Master!$C$44-Inputs_Master!$C$20)*((1-(1+Inputs_Master!$C$15)^(-Inputs_Master!$C$45))/Inputs_Master!$C$15),0),0) -> #N/A | D37: =IF(D7=1,IF(D5=0,Inputs_Master!$C$41*(Inputs_Master!$C$44-Inputs_Master!$C$20)*((1-(1+Inputs_Master!$C$15)^(-Inputs_Master!$C$45))/Inputs_Master!$C$15),0),0) -> 0 | E37: =IF(E7=1,IF(E5=0,Inputs_Master!$C$41*(Inputs_Master!$C$44-Inputs_Master!$C$20)*((1-(1+Inputs_Master!$C$15)^(-Inputs_Master!$C$45))/Inputs_Master!$C$15),0),0) -> 0 | F37: =IF(F7=1,IF(F5=0,Inputs_Master!$C$41*(Inputs_Master!$C$44-Inputs_Master!$C$20)*((1-(1+Inputs_Master!$C$15)^(-Inputs_Master!$C$45))/Inputs_Master!$C$15),0),0) -> 0 | G37: =IF(G7=1,IF(G5=0,Inputs_Master!$C$41*(Inputs_Master!$C$44-Inputs_Master!$C$20)*((1-(1+Inputs_Master!$C$15)^(-Inputs_Master!$C$45))/Inputs_Master!$C$15),0),0) -> 0 | H37: =IF(H7=1,IF(H5=0,Inputs_Master!$C$41*(Inputs_Master!$C$44-Inputs_Master!$C$20)*((1-(1+Inputs_Master!$C$15)^(-Inputs_Master!$C$45))/Inputs_Master!$C$15),0),0) -> 0 | I37: =IF(I7=1,IF(I5=0,Inputs_Master!$C$41*(Inputs_Master!$C$44-Inputs_Master!$C$20)*((1-(1+Inputs_Master!$C$15)^(-Inputs_Master!$C$45))/Inputs_Master!$C$15),0),0) -> 0 | J37: =IF(J7=1,IF(J5=0,Inputs_Master!$C$41*(Inputs_Master!$C$44-Inputs_Master!$C$20)*((1-(1+Inputs_Master!$C$15)^(-Inputs_Master!$C$45))/Inputs_Master!$C$15),0),0) -> 0 | ... AJ37: =IF(AJ7=1,IF(AJ5=0,Inputs_Master!$C$41*(Inputs_Master!$C$44-Inputs_Master!$C$20)*((1-(1+Inputs_Master!$C$15)^(-Inputs_Master!$C$45))/Inputs_Master!$C$15),0),0) -> 0
B38: TOTAL COMP NEUTRALITY | C38: =IF(C7=1,C35+C36+C37,0) -> #N/A | D38: =IF(D7=1,D35+D36+D37,0) -> 0 | E38: =IF(E7=1,E35+E36+E37,0) -> 0 | F38: =IF(F7=1,F35+F36+F37,0) -> #NUM! | G38: =IF(G7=1,G35+G36+G37,0) -> #NUM! | H38: =IF(H7=1,H35+H36+H37,0) -> #NUM! | I38: =IF(I7=1,I35+I36+I37,0) -> #NUM! | J38: =IF(J7=1,J35+J36+J37,0) -> #NUM! | ... AJ38: =IF(AJ7=1,AJ35+AJ36+AJ37,0) -> #NUM!
B40: RESIDUAL VALUE
B41: Asset Residual Credit | C41: =IF(C7=1,IF(C5=Inputs_Master!$C$10,-(Inputs_Master!$C$70+Inputs_Master!$C$28*(Inputs_Master!$C$69-Inputs_Master!$C$10)/Inputs_Master!$C$69),0),0) -> 0 | D41: =IF(D7=1,IF(D5=Inputs_Master!$C$10,-(Inputs_Master!$C$70+Inputs_Master!$C$28*(Inputs_Master!$C$69-Inputs_Master!$C$10)/Inputs_Master!$C$69),0),0) -> 0 | E41: =IF(E7=1,IF(E5=Inputs_Master!$C$10,-(Inputs_Master!$C$70+Inputs_Master!$C$28*(Inputs_Master!$C$69-Inputs_Master!$C$10)/Inputs_Master!$C$69),0),0) -> 0 | F41: =IF(F7=1,IF(F5=Inputs_Master!$C$10,-(Inputs_Master!$C$70+Inputs_Master!$C$28*(Inputs_Master!$C$69-Inputs_Master!$C$10)/Inputs_Master!$C$69),0),0) -> 0 | G41: =IF(G7=1,IF(G5=Inputs_Master!$C$10,-(Inputs_Master!$C$70+Inputs_Master!$C$28*(Inputs_Master!$C$69-Inputs_Master!$C$10)/Inputs_Master!$C$69),0),0) -> 0 | H41: =IF(H7=1,IF(H5=Inputs_Master!$C$10,-(Inputs_Master!$C$70+Inputs_Master!$C$28*(Inputs_Master!$C$69-Inputs_Master!$C$10)/Inputs_Master!$C$69),0),0) -> 0 | I41: =IF(I7=1,IF(I5=Inputs_Master!$C$10,-(Inputs_Master!$C$70+Inputs_Master!$C$28*(Inputs_Master!$C$69-Inputs_Master!$C$10)/Inputs_Master!$C$69),0),0) -> 0 | J41: =IF(J7=1,IF(J5=Inputs_Master!$C$10,-(Inputs_Master!$C$70+Inputs_Master!$C$28*(Inputs_Master!$C$69-Inputs_Master!$C$10)/Inputs_Master!$C$69),0),0) -> 0 | ... AJ41: =IF(AJ7=1,IF(AJ5=Inputs_Master!$C$10,-(Inputs_Master!$C$70+Inputs_Master!$C$28*(Inputs_Master!$C$69-Inputs_Master!$C$10)/Inputs_Master!$C$69),0),0) -> 972
B43: TOTAL PSC CASH FLOWS
B44: Annual Cash Flow | C44: =IF(C7=1,C16+C26+C32+C38+C41,0) -> #N/A | D44: =IF(D7=1,D16+D26+D32+D38+D41,0) -> 8.9128736 | E44: =IF(E7=1,E16+E26+E32+E38+E41,0) -> 8.7165404 | F44: =IF(F7=1,F16+F26+F32+F38+F41,0) -> #N/A | G44: =IF(G7=1,G16+G26+G32+G38+G41,0) -> #N/A | H44: =IF(H7=1,H16+H26+H32+H38+H41,0) -> #N/A | I44: =IF(I7=1,I16+I26+I32+I38+I41,0) -> #N/A | J44: =IF(J7=1,J16+J26+J32+J38+J41,0) -> #N/A | ... AJ44: =IF(AJ7=1,AJ16+AJ26+AJ32+AJ38+AJ41,0) -> #N/A
B45: Discount Factor | C45: =IF(C7=1,1/POWER(1+Inputs_Master!$C$16,C5),0) -> #N/A | D45: =IF(D7=1,1/POWER(1+Inputs_Master!$C$16,D5),0) -> #N/A | E45: =IF(E7=1,1/POWER(1+Inputs_Master!$C$16,E5),0) -> #N/A | F45: =IF(F7=1,1/POWER(1+Inputs_Master!$C$16,F5),0) -> #N/A | G45: =IF(G7=1,1/POWER(1+Inputs_Master!$C$16,G5),0) -> #N/A | H45: =IF(H7=1,1/POWER(1+Inputs_Master!$C$16,H5),0) -> #N/A | I45: =IF(I7=1,1/POWER(1+Inputs_Master!$C$16,I5),0) -> #N/A | J45: =IF(J7=1,1/POWER(1+Inputs_Master!$C$16,J5),0) -> #N/A | ... AJ45: =IF(AJ7=1,1/POWER(1+Inputs_Master!$C$16,AJ5),0) -> #N/A
B46: Present Value | C46: =IF(C7=1,C44*C45,0) -> #N/A | D46: =IF(D7=1,D44*D45,0) -> #N/A | E46: =IF(E7=1,E44*E45,0) -> #N/A | F46: =IF(F7=1,F44*F45,0) -> #N/A | G46: =IF(G7=1,G44*G45,0) -> #N/A | H46: =IF(H7=1,H44*H45,0) -> #N/A | I46: =IF(I7=1,I44*I45,0) -> #N/A | J46: =IF(J7=1,J44*J45,0) -> #N/A | ... AJ46: =IF(AJ7=1,AJ44*AJ45,0) -> #N/A
B48: PSC NET PRESENT VALUE | C48: =SUM(C46:AJ46) -> #N/A
B50: COMPONENT NPVs (for VfM)
...

Sheet Calc_P3
B2: P3 CALCULATION ENGINE — DBFM STRUCTURE
B5: Year | C5: 0 | D5: 1 | E5: 2 | F5: 3 | G5: 4 | H5: 5 | I5: 6 | J5: 7 | K5: 8 | L5: 9 | M5: 10 | N5: 11 | O5: 12 | P5: 13 | Q5: 14 | R5: 15 | S5: 16 | T5: 17 | U5: 18 | V5: 19 | W5: 20 | X5: 21 | Y5: 22 | Z5: 23 | AA5: 24 | AB5: 25 | AC5: 26 | AD5: 27 | AE5: 28 | AF5: 29 | AG5: 30 | AH5: 31 | AI5: 32 | AJ5: 33
B6: Phase | C6: =IF(C5<Inputs_Master!$C$8,"Construction","Operating") -> Construction | D6: =IF(D5<Inputs_Master!$C$8,"Construction","Operating") -> Construction | E6: =IF(E5<Inputs_Master!$C$8,"Construction","Operating") -> Construction | F6: =IF(F5<Inputs_Master!$C$8,"Construction","Operating") -> Operating | G6: =IF(G5<Inputs_Master!$C$8,"Construction","Operating") -> Operating | H6: =IF(H5<Inputs_Master!$C$8,"Construction","Operating") -> Operating | I6: =IF(I5<Inputs_Master!$C$8,"Construction","Operating") -> Operating | J6: =IF(J5<Inputs_Master!$C$8,"Construction","Operating") -> Operating | ... AJ6: =IF(AJ5<Inputs_Master!$C$8,"Construction","Operating") -> Operating
B7: Active | C7: =IF(C5<=Inputs_Master!$C$10,1,0) -> 1 | D7: =IF(D5<=Inputs_Master!$C$10,1,0) -> 1 | E7: =IF(E5<=Inputs_Master!$C$10,1,0) -> 1 | F7: =IF(F5<=Inputs_Master!$C$10,1,0) -> 1 | G7: =IF(G5<=Inputs_Master!$C$10,1,0) -> 1 | H7: =IF(H5<=Inputs_Master!$C$10,1,0) -> 1 | I7: =IF(I5<=Inputs_Master!$C$10,1,0) -> 1 | J7: =IF(J5<=Inputs_Master!$C$10,1,0) -> 1 | ... AJ7: =IF(AJ5<=Inputs_Master!$C$10,1,0) -> 1
B9: P3 CONSTRUCTION COSTS
B10: P3 Adjusted Capital | C10: =IF(C7=1,IF(C6="Construction",Inputs_Master!$C$36*Inputs_Master!$C$30,0),0) -> 625.25 | D10: =IF(D7=1,IF(D6="Construction",Inputs_Master!$C$36*Inputs_Master!$C$31,0),0) -> 0.2501 | E10: =IF(E7=1,IF(E6="Construction",Inputs_Master!$C$36*Inputs_Master!$C$32,0),0) -> 0 | F10: 0 | G10: 0 | H10: 0 | I10: 0 | J10: 0 | K10: 0 | L10: 0 | M10: 0 | N10: 0 | O10: 0 | P10: 0 | Q10: 0 | R10: 0 | S10: 0 | T10: 0 | U10: 0 | V10: 0 | W10: 0 | X10: 0 | Y10: 0 | Z10: 0 | AA10: 0 | AB10: 0 | AC10: 0 | AD10: 0 | AE10: 0 | AF10: 0 | AG10: 0 | AH10: 0 | AI10: 0 | AJ10: 0
B11: Construction Escalation | C11: =IF(C7=1,IF(C6="Construction",POWER(1+Inputs_Master!$C$18,C5),1),0) -> 1 | D11: =IF(D7=1,IF(D6="Construction",POWER(1+Inputs_Master!$C$18,D5),1),0) -> 1.06 | E11: =IF(E7=1,IF(E6="Construction",POWER(1+Inputs_Master!$C$18,E5),1),0) -> 1.1236 | F11: =IF(F7=1,IF(F6="Construction",POWER(1+Inputs_Master!$C$18,F5),1),0) -> 1 | G11: =IF(G7=1,IF(G6="Construction",POWER(1+Inputs_Master!$C$18,G5),1),0) -> 1 | H11: =IF(H7=1,IF(H6="Construction",POWER(1+Inputs_Master!$C$18,H5),1),0) -> 1 | I11: =IF(I7=1,IF(I6="Construction",POWER(1+Inputs_Master!$C$18,I5),1),0) -> 1 | J11: =IF(J7=1,IF(J6="Construction",POWER(1+Inputs_Master!$C$18,J5),1),0) -> 1 | ... AJ11: =IF(AJ7=1,IF(AJ6="Construction",POWER(1+Inputs_Master!$C$18,AJ5),1),0) -> 1
B12: TOTAL P3 CONSTRUCTION | C12: =IF(C7=1,C10*C11,0) -> 625.25 | D12: =IF(D7=1,D10*D11,0) -> 0.265106 | E12: =IF(E7=1,E10*E11,0) -> 0 | F12: =IF(F7=1,F10*F11,0) -> 0 | G12: =IF(G7=1,G10*G11,0) -> 0 | H12: =IF(H7=1,H10*H11,0) -> 0 | I12: =IF(I7=1,I10*I11,0) -> 0 | J12: =IF(J7=1,J10*J11,0) -> 0 | ... AJ12: =IF(AJ7=1,AJ10*AJ11,0) -> 0
B14: DEBT SERVICE SCHEDULE
B15: Debt Drawn | C15: =IF(C7=1,IF(C6="Construction",C12*Inputs_Master!$C$38,0),0) -> 0 | D15: =IF(D7=1,IF(D6="Construction",D12*Inputs_Master!$C$38,0),0) -> 0 | E15: =IF(E7=1,IF(E6="Construction",E12*Inputs_Master!$C$38,0),0) -> 0 | F15: =IF(F7=1,IF(F6="Construction",F12*Inputs_Master!$C$38,0),0) -> 0 | G15: =IF(G7=1,IF(G6="Construction",G12*Inputs_Master!$C$38,0),0) -> 0 | H15: =IF(H7=1,IF(H6="Construction",H12*Inputs_Master!$C$38,0),0) -> 0 | I15: =IF(I7=1,IF(I6="Construction",I12*Inputs_Master!$C$38,0),0) -> 0 | J15: =IF(J7=1,IF(J6="Construction",J12*Inputs_Master!$C$38,0),0) -> 0 | ... AJ15: =IF(AJ7=1,IF(AJ6="Construction",AJ12*Inputs_Master!$C$38,0),0) -> 0
B16: Opening Balance | C16: 0 | D16: =C20 -> 0 | E16: =D20 -> 0 | F16: =E20 -> 0 | G16: =F20 -> #NUM! | H16: =G20 -> #NUM! | I16: =H20 -> #NUM! | J16: =I20 -> #NUM! | K16: =J20 -> #NUM! | ... AJ16: =AI20 -> #NUM!
B17: Interest Expense | C17: =IF(C7=1,C16*Inputs_Master!$C$44,0) -> 0 | D17: =IF(D7=1,D16*Inputs_Master!$C$44,0) -> 0 | E17: =IF(E7=1,E16*Inputs_Master!$C$44,0) -> 0 | F17: =IF(F7=1,F16*Inputs_Master!$C$44,0) -> 0 | G17: =IF(G7=1,G16*Inputs_Master!$C$44,0) -> #NUM! | H17: =IF(H7=1,H16*Inputs_Master!$C$44,0) -> #NUM! | I17: =IF(I7=1,I16*Inputs_Master!$C$44,0) -> #NUM! | J17: =IF(J7=1,J16*Inputs_Master!$C$44,0) -> #NUM! | ... AJ17: =IF(AJ7=1,AJ16*Inputs_Master!$C$44,0) -> #NUM!
B18: Principal Repayment | C18: =IF(C7=1,IF(C6="Operating",C19-C17,0),0) -> 0 | D18: =IF(D7=1,IF(D6="Operating",D19-D17,0),0) -> 0 | E18: =IF(E7=1,IF(E6="Operating",E19-E17,0),0) -> 0 | F18: =IF(F7=1,IF(F6="Operating",F19-F17,0),0) -> #NUM! | G18: =IF(G7=1,IF(G6="Operating",G19-G17,0),0) -> #NUM! | H18: =IF(H7=1,IF(H6="Operating",H19-H17,0),0) -> #NUM! | I18: =IF(I7=1,IF(I6="Operating",I19-I17,0),0) -> #NUM! | J18: =IF(J7=1,IF(J6="Operating",J19-J17,0),0) -> #NUM! | ... AJ18: =IF(AJ7=1,IF(AJ6="Operating",AJ19-AJ17,0),0) -> #NUM!
B19: Annual Debt Service | C19: =IF(C7=1,IF(C6="Operating",Inputs_Master!$C$48,0),0) -> 0 | D19: =IF(D7=1,IF(D6="Operating",Inputs_Master!$C$48,0),0) -> 0 | E19: =IF(E7=1,IF(E6="Operating",Inputs_Master!$C$48,0),0) -> 0 | F19: =IF(F7=1,IF(F6="Operating",Inputs_Master!$C$48,0),0) -> #NUM! | G19: =IF(G7=1,IF(G6="Operating",Inputs_Master!$C$48,0),0) -> #NUM! | H19: =IF(H7=1,IF(H6="Operating",Inputs_Master!$C$48,0),0) -> #NUM! | I19: =IF(I7=1,IF(I6="Operating",Inputs_Master!$C$48,0),0) -> #NUM! | J19: =IF(J7=1,IF(J6="Operating",Inputs_Master!$C$48,0),0) -> #NUM! | ... AJ19: =IF(AJ7=1,IF(AJ6="Operating",Inputs_Master!$C$48,0),0) -> #NUM!
B20: Closing Balance | C20: =IF(C7=1,C16+C15-C18,0) -> 0 | D20: =IF(D7=1,D16+D15-D18,0) -> 0 | E20: =IF(E7=1,E16+E15-E18,0) -> 0 | F20: =IF(F7=1,F16+F15-F18,0) -> #NUM! | G20: =IF(G7=1,G16+G15-G18,0) -> #NUM! | H20: =IF(H7=1,H16+H15-H18,0) -> #NUM! | I20: =IF(I7=1,I16+I15-I18,0) -> #NUM! | J20: =IF(J7=1,J16+J15-J18,0) -> #NUM! | ... AJ20: =IF(AJ7=1,AJ16+AJ15-AJ18,0) -> #NUM!
B22: EQUITY CASH FLOWS
B23: Equity Injection | C23: =IF(C7=1,IF(C6="Construction",C12*(1-Inputs_Master!$C$38),0),0) -> 625.25 | D23: =IF(D7=1,IF(D6="Construction",D12*(1-Inputs_Master!$C$38),0),0) -> 0.265106 | E23: =IF(E7=1,IF(E6="Construction",E12*(1-Inputs_Master!$C$38),0),0) -> 0 | F23: =IF(F7=1,IF(F6="Construction",F12*(1-Inputs_Master!$C$38),0),0) -> 0 | G23: =IF(G7=1,IF(G6="Construction",G12*(1-Inputs_Master!$C$38),0),0) -> 0 | H23: =IF(H7=1,IF(H6="Construction",H12*(1-Inputs_Master!$C$38),0),0) -> 0 | I23: =IF(I7=1,IF(I6="Construction",I12*(1-Inputs_Master!$C$38),0),0) -> 0 | J23: =IF(J7=1,IF(J6="Construction",J12*(1-Inputs_Master!$C$38),0),0) -> 0 | ... AJ23: =IF(AJ7=1,IF(AJ6="Construction",AJ12*(1-Inputs_Master!$C$38),0),0) -> 0
B25: P3 OPERATING COSTS
B26: O&M Costs | C26: =IF(C7=1,IF(C6="Operating",Inputs_Master!$C$60*(1+Inputs_Master!$C$61)*(1-Inputs_Master!$C$62)*POWER(1+Inputs_Master!$C$19,C5-Inputs_Master!$C$8),0),0) -> 0 | D26: =IF(D7=1,IF(D6="Operating",Inputs_Master!$C$60*(1+Inputs_Master!$C$61)*(1-Inputs_Master!$C$62)*POWER(1+Inputs_Master!$C$19,D5-Inputs_Master!$C$8),0),0) -> 0 | E26: =IF(E7=1,IF(E6="Operating",Inputs_Master!$C$60*(1+Inputs_Master!$C$61)*(1-Inputs_Master!$C$62)*POWER(1+Inputs_Master!$C$19,E5-Inputs_Master!$C$8),0),0) -> 0 | F26: =IF(F7=1,IF(F6="Operating",Inputs_Master!$C$60*(1+Inputs_Master!$C$61)*(1-Inputs_Master!$C$62)*POWER(1+Inputs_Master!$C$19,F5-Inputs_Master!$C$8),0),0) -> #NUM! | G26: =IF(G7=1,IF(G6="Operating",Inputs_Master!$C$60*(1+Inputs_Master!$C$61)*(1-Inputs_Master!$C$62)*POWER(1+Inputs_Master!$C$19,G5-Inputs_Master!$C$8),0),0) -> #NUM! | H26: =IF(H7=1,IF(H6="Operating",Inputs_Master!$C$60*(1+Inputs_Master!$C$61)*(1-Inputs_Master!$C$62)*POWER(1+Inputs_Master!$C$19,H5-Inputs_Master!$C$8),0),0) -> #NUM! | I26: =IF(I7=1,IF(I6="Operating",Inputs_Master!$C$60*(1+Inputs_Master!$C$61)*(1-Inputs_Master!$C$62)*POWER(1+Inputs_Master!$C$19,I5-Inputs_Master!$C$8),0),0) -> #NUM! | J26: =IF(J7=1,IF(J6="Operating",Inputs_Master!$C$60*(1+Inputs_Master!$C$61)*(1-Inputs_Master!$C$62)*POWER(1+Inputs_Master!$C$19,J5-Inputs_Master!$C$8),0),0) -> #NUM! | ... AJ26: =IF(AJ7=1,IF(AJ6="Operating",Inputs_Master!$C$60*(1+Inputs_Master!$C$61)*(1-Inputs_Master!$C$62)*POWER(1+Inputs_Master!$C$19,AJ5-Inputs_Master!$C$8),0),0) -> #NUM!
B27: Lifecycle Costs | C27: =IF(C7=1,IF(C6="Operating",IF(MOD(C5-Inputs_Master!$C$8,15)=0,Inputs_Master!$C$54*3,Inputs_Master!$C$54*0.3)*POWER(1+Inputs_Master!$C$19,C5-Inputs_Master!$C$8),0),0) -> 0 | D27: =IF(D7=1,IF(D6="Operating",IF(MOD(D5-Inputs_Master!$C$8,15)=0,Inputs_Master!$C$54*3,Inputs_Master!$C$54*0.3)*POWER(1+Inputs_Master!$C$19,D5-Inputs_Master!$C$8),0),0) -> 0 | E27: =IF(E7=1,IF(E6="Operating",IF(MOD(E5-Inputs_Master!$C$8,15)=0,Inputs_Master!$C$54*3,Inputs_Master!$C$54*0.3)*POWER(1+Inputs_Master!$C$19,E5-Inputs_Master!$C$8),0),0) -> 0 | F27: =IF(F7=1,IF(F6="Operating",IF(MOD(F5-Inputs_Master!$C$8,15)=0,Inputs_Master!$C$54*3,Inputs_Master!$C$54*0.3)*POWER(1+Inputs_Master!$C$19,F5-Inputs_Master!$C$8),0),0) -> #N/A | G27: =IF(G7=1,IF(G6="Operating",IF(MOD(G5-Inputs_Master!$C$8,15)=0,Inputs_Master!$C$54*3,Inputs_Master!$C$54*0.3)*POWER(1+Inputs_Master!$C$19,G5-Inputs_Master!$C$8),0),0) -> #N/A | H27: =IF(H7=1,IF(H6="Operating",IF(MOD(H5-Inputs_Master!$C$8,15)=0,Inputs_Master!$C$54*3,Inputs_Master!$C$54*0.3)*POWER(1+Inputs_Master!$C$19,H5-Inputs_Master!$C$8),0),0) -> #N/A | I27: =IF(I7=1,IF(I6="Operating",IF(MOD(I5-Inputs_Master!$C$8,15)=0,Inputs_Master!$C$54*3,Inputs_Master!$C$54*0.3)*POWER(1+Inputs_Master!$C$19,I5-Inputs_Master!$C$8),0),0) -> #N/A | J27: =IF(J7=1,IF(J6="Operating",IF(MOD(J5-Inputs_Master!$C$8,15)=0,Inputs_Master!$C$54*3,Inputs_Master!$C$54*0.3)*POWER(1+Inputs_Master!$C$19,J5-Inputs_Master!$C$8),0),0) -> #N/A | ... AJ27: =IF(AJ7=1,IF(AJ6="Operating",IF(MOD(AJ5-Inputs_Master!$C$8,15)=0,Inputs_Master!$C$54*3,Inputs_Master!$C$54*0.3)*POWER(1+Inputs_Master!$C$19,AJ5-Inputs_Master!$C$8),0),0) -> #N/A
B28: Insurance | C28: =IF(C7=1,IF(C6="Operating",Inputs_Master!$C$63*POWER(1+Inputs_Master!$C$19,C5-Inputs_Master!$C$8),0),0) -> 0 | D28: =IF(D7=1,IF(D6="Operating",Inputs_Master!$C$63*POWER(1+Inputs_Master!$C$19,D5-Inputs_Master!$C$8),0),0) -> 0 | E28: =IF(E7=1,IF(E6="Operating",Inputs_Master!$C$63*POWER(1+Inputs_Master!$C$19,E5-Inputs_Master!$C$8),0),0) -> 0 | F28: =IF(F7=1,IF(F6="Operating",Inputs_Master!$C$63*POWER(1+Inputs_Master!$C$19,F5-Inputs_Master!$C$8),0),0) -> #N/A | G28: =IF(G7=1,IF(G6="Operating",Inputs_Master!$C$63*POWER(1+Inputs_Master!$C$19,G5-Inputs_Master!$C$8),0),0) -> #N/A | H28: =IF(H7=1,IF(H6="Operating",Inputs_Master!$C$63*POWER(1+Inputs_Master!$C$19,H5-Inputs_Master!$C$8),0),0) -> #N/A | I28: =IF(I7=1,IF(I6="Operating",Inputs_Master!$C$63*POWER(1+Inputs_Master!$C$19,I5-Inputs_Master!$C$8),0),0) -> #N/A | J28: =IF(J7=1,IF(J6="Operating",Inputs_Master!$C$63*POWER(1+Inputs_Master!$C$19,J5-Inputs_Master!$C$8),0),0) -> #N/A | ... AJ28: =IF(AJ7=1,IF(AJ6="Operating",Inputs_Master!$C$63*POWER(1+Inputs_Master!$C$19,AJ5-Inputs_Master!$C$8),0),0) -> #N/A
B29: TOTAL P3 OPERATING | C29: =IF(C7=1,C26+C27+C28,0) -> 0 | D29: =IF(D7=1,D26+D27+D28,0) -> 0 | E29: =IF(E7=1,E26+E27+E28,0) -> 0 | F29: =IF(F7=1,F26+F27+F28,0) -> #N/A | G29: =IF(G7=1,G26+G27+G28,0) -> #N/A | H29: =IF(H7=1,H26+H27+H28,0) -> #N/A | I29: =IF(I7=1,I26+I27+I28,0) -> #N/A | J29: =IF(J7=1,J26+J27+J28,0) -> #N/A | ... AJ29: =IF(AJ7=1,AJ26+AJ27+AJ28,0) -> #N/A
B31: SERVICE PAYMENT TO SPV
B32: Base Service Payment | C32: =IF(C7=1,IF(C6="Operating",Inputs_Master!$C$59*POWER(1+Inputs_Master!$C$17,C5-Inputs_Master!$C$8),0),0) -> 0 | D32: =IF(D7=1,IF(D6="Operating",Inputs_Master!$C$59*POWER(1+Inputs_Master!$C$17,D5-Inputs_Master!$C$8),0),0) -> 0 | E32: =IF(E7=1,IF(E6="Operating",Inputs_Master!$C$59*POWER(1+Inputs_Master!$C$17,E5-Inputs_Master!$C$8),0),0) -> 0 | F32: =IF(F7=1,IF(F6="Operating",Inputs_Master!$C$59*POWER(1+Inputs_Master!$C$17,F5-Inputs_Master!$C$8),0),0) -> 0.8 | G32: =IF(G7=1,IF(G6="Operating",Inputs_Master!$C$59*POWER(1+Inputs_Master!$C$17,G5-Inputs_Master!$C$8),0),0) -> 0.8 | H32: =IF(H7=1,IF(H6="Operating",Inputs_Master!$C$59*POWER(1+Inputs_Master!$C$17,H5-Inputs_Master!$C$8),0),0) -> 0.8 | I32: =IF(I7=1,IF(I6="Operating",Inputs_Master!$C$59*POWER(1+Inputs_Master!$C$17,I5-Inputs_Master!$C$8),0),0) -> 0.8 | J32: =IF(J7=1,IF(J6="Operating",Inputs_Master!$C$59*POWER(1+Inputs_Master!$C$17,J5-Inputs_Master!$C$8),0),0) -> 0.8 | ... AJ32: =IF(AJ7=1,IF(AJ6="Operating",Inputs_Master!$C$59*POWER(1+Inputs_Master!$C$17,AJ5-Inputs_Master!$C$8),0),0) -> 0.8
B33: Performance Deductions | C33: =IF(C7=1,-C32*Inputs_Master!$C$62,0) -> 0 | D33: =IF(D7=1,-D32*Inputs_Master!$C$62,0) -> 0 | E33: =IF(E7=1,-E32*Inputs_Master!$C$62,0) -> 0 | F33: =IF(F7=1,-F32*Inputs_Master!$C$62,0) -> 0 | G33: =IF(G7=1,-G32*Inputs_Master!$C$62,0) -> 0 | H33: =IF(H7=1,-H32*Inputs_Master!$C$62,0) -> 0 | I33: =IF(I7=1,-I32*Inputs_Master!$C$62,0) -> 0 | J33: =IF(J7=1,-J32*Inputs_Master!$C$62,0) -> 0 | ... AJ33: =IF(AJ7=1,-AJ32*Inputs_Master!$C$62,0) -> 0
B34: NET SERVICE PAYMENT | C34: =IF(C7=1,C32+C33,0) -> 0 | D34: =IF(D7=1,D32+D33,0) -> 0 | E34: =IF(E7=1,E32+E33,0) -> 0 | F34: =IF(F7=1,F32+F33,0) -> 0.8 | G34: =IF(G7=1,G32+G33,0) -> 0.8 | H34: =IF(H7=1,H32+H33,0) -> 0.8 | I34: =IF(I7=1,I32+I33,0) -> 0.8 | J34: =IF(J7=1,J32+J33,0) -> 0.8 | ... AJ34: =IF(AJ7=1,AJ32+AJ33,0) -> 0.8
B36: SPV OVERHEAD & GOA COSTS
B37: SPV Management | C37: =IF(C7=1,IF(C6="Operating",Inputs_Master!$C$64*POWER(1+Inputs_Master!$C$19,C5-Inputs_Master!$C$8),0),0) -> 0 | D37: =IF(D7=1,IF(D6="Operating",Inputs_Master!$C$64*POWER(1+Inputs_Master!$C$19,D5-Inputs_Master!$C$8),0),0) -> 0 | E37: =IF(E7=1,IF(E6="Operating",Inputs_Master!$C$64*POWER(1+Inputs_Master!$C$19,E5-Inputs_Master!$C$8),0),0) -> 0 | F37: =IF(F7=1,IF(F6="Operating",Inputs_Master!$C$64*POWER(1+Inputs_Master!$C$19,F5-Inputs_Master!$C$8),0),0) -> #N/A | G37: =IF(G7=1,IF(G6="Operating",Inputs_Master!$C$64*POWER(1+Inputs_Master!$C$19,G5-Inputs_Master!$C$8),0),0) -> #N/A | H37: =IF(H7=1,IF(H6="Operating",Inputs_Master!$C$64*POWER(1+Inputs_Master!$C$19,H5-Inputs_Master!$C$8),0),0) -> #N/A | I37: =IF(I7=1,IF(I6="Operating",Inputs_Master!$C$64*POWER(1+Inputs_Master!$C$19,I5-Inputs_Master!$C$8),0),0) -> #N/A | J37: =IF(J7=1,IF(J6="Operating",Inputs_Master!$C$64*POWER(1+Inputs_Master!$C$19,J5-Inputs_Master!$C$8),0),0) -> #N/A | ... AJ37: =IF(AJ7=1,IF(AJ6="Operating",Inputs_Master!$C$64*POWER(1+Inputs_Master!$C$19,AJ5-Inputs_Master!$C$8),0),0) -> #N/A
B38: GOA Monitoring | C38: =IF(C7=1,IF(C6="Operating",Inputs_Master!$C$65*POWER(1+Inputs_Master!$C$19,C5-Inputs_Master!$C$8),0),0) -> 0 | D38: =IF(D7=1,IF(D6="Operating",Inputs_Master!$C$65*POWER(1+Inputs_Master!$C$19,D5-Inputs_Master!$C$8),0),0) -> 0 | E38: =IF(E7=1,IF(E6="Operating",Inputs_Master!$C$65*POWER(1+Inputs_Master!$C$19,E5-Inputs_Master!$C$8),0),0) -> 0 | F38: =IF(F7=1,IF(F6="Operating",Inputs_Master!$C$65*POWER(1+Inputs_Master!$C$19,F5-Inputs_Master!$C$8),0),0) -> #N/A | G38: =IF(G7=1,IF(G6="Operating",Inputs_Master!$C$65*POWER(1+Inputs_Master!$C$19,G5-Inputs_Master!$C$8),0),0) -> #N/A | H38: =IF(H7=1,IF(H6="Operating",Inputs_Master!$C$65*POWER(1+Inputs_Master!$C$19,H5-Inputs_Master!$C$8),0),0) -> #N/A | I38: =IF(I7=1,IF(I6="Operating",Inputs_Master!$C$65*POWER(1+Inputs_Master!$C$19,I5-Inputs_Master!$C$8),0),0) -> #N/A | J38: =IF(J7=1,IF(J6="Operating",Inputs_Master!$C$65*POWER(1+Inputs_Master!$C$19,J5-Inputs_Master!$C$8),0),0) -> #N/A | ... AJ38: =IF(AJ7=1,IF(AJ6="Operating",Inputs_Master!$C$65*POWER(1+Inputs_Master!$C$19,AJ5-Inputs_Master!$C$8),0),0) -> #N/A
B39: Transaction Costs | C39: =IF(C7=1,IF(C5=0,Inputs_Master!$C$66,0),0) -> 0.02 | D39: =IF(D7=1,IF(D5=0,Inputs_Master!$C$66,0),0) -> 0 | E39: =IF(E7=1,IF(E5=0,Inputs_Master!$C$66,0),0) -> 0 | F39: =IF(F7=1,IF(F5=0,Inputs_Master!$C$66,0),0) -> 0 | G39: =IF(G7=1,IF(G5=0,Inputs_Master!$C$66,0),0) -> 0 | H39: =IF(H7=1,IF(H5=0,Inputs_Master!$C$66,0),0) -> 0 | I39: =IF(I7=1,IF(I5=0,Inputs_Master!$C$66,0),0) -> 0 | J39: =IF(J7=1,IF(J5=0,Inputs_Master!$C$66,0),0) -> 0 | ... AJ39: =IF(AJ7=1,IF(AJ5=0,Inputs_Master!$C$66,0),0) -> 0
B41: P3 RETAINED RISKS (GOA)
B42: Shared Risks (GOA portion) | C42: =IF(C7=1,Risk_Register!$N$18/Inputs_Master!$C$10,0) -> 1.1901768 | D42: =IF(D7=1,Risk_Register!$N$18/Inputs_Master!$C$10,0) -> 1.1901768 | E42: =IF(E7=1,Risk_Register!$N$18/Inputs_Master!$C$10,0) -> 1.1901768 | F42: =IF(F7=1,Risk_Register!$N$18/Inputs_Master!$C$10,0) -> 1.1901768 | G42: =IF(G7=1,Risk_Register!$N$18/Inputs_Master!$C$10,0) -> 1.1901768 | H42: =IF(H7=1,Risk_Register!$N$18/Inputs_Master!$C$10,0) -> 1.1901768 | I42: =IF(I7=1,Risk_Register!$N$18/Inputs_Master!$C$10,0) -> 1.1901768 | J42: =IF(J7=1,Risk_Register!$N$18/Inputs_Master!$C$10,0) -> 1.1901768 | ... AJ42: =IF(AJ7=1,Risk_Register!$N$18/Inputs_Master!$C$10,0) -> 1.1901768
B44: RESIDUAL VALUE
B45: P3 Residual Credit | C45: =IF(C7=1,IF(C5=Inputs_Master!$C$10,-(Inputs_Master!$C$70+Inputs_Master!$C$28*(Inputs_Master!$C$69-Inputs_Master!$C$10)/Inputs_Master!$C$69)*(1-Inputs_Master!$C$71-Inputs_Master!$C$72),0),0) -> 0 | D45: =IF(D7=1,IF(D5=Inputs_Master!$C$10,-(Inputs_Master!$C$70+Inputs_Master!$C$28*(Inputs_Master!$C$69-Inputs_Master!$C$10)/Inputs_Master!$C$69)*(1-Inputs_Master!$C$71-Inputs_Master!$C$72),0),0) -> 0 | E45: =IF(E7=1,IF(E5=Inputs_Master!$C$10,-(Inputs_Master!$C$70+Inputs_Master!$C$28*(Inputs_Master!$C$69-Inputs_Master!$C$10)/Inputs_Master!$C$69)*(1-Inputs_Master!$C$71-Inputs_Master!$C$72),0),0) -> 0 | F45: =IF(F7=1,IF(F5=Inputs_Master!$C$10,-(Inputs_Master!$C$70+Inputs_Master!$C$28*(Inputs_Master!$C$69-Inputs_Master!$C$10)/Inputs_Master!$C$69)*(1-Inputs_Master!$C$71-Inputs_Master!$C$72),0),0) -> 0 | G45: =IF(G7=1,IF(G5=Inputs_Master!$C$10,-(Inputs_Master!$C$70+Inputs_Master!$C$28*(Inputs_Master!$C$69-Inputs_Master!$C$10)/Inputs_Master!$C$69)*(1-Inputs_Master!$C$71-Inputs_Master!$C$72),0),0) -> 0 | H45: =IF(H7=1,IF(H5=Inputs_Master!$C$10,-(Inputs_Master!$C$70+Inputs_Master!$C$28*(Inputs_Master!$C$69-Inputs_Master!$C$10)/Inputs_Master!$C$69)*(1-Inputs_Master!$C$71-Inputs_Master!$C$72),0),0) -> 0 | I45: =IF(I7=1,IF(I5=Inputs_Master!$C$10,-(Inputs_Master!$C$70+Inputs_Master!$C$28*(Inputs_Master!$C$69-Inputs_Master!$C$10)/Inputs_Master!$C$69)*(1-Inputs_Master!$C$71-Inputs_Master!$C$72),0),0) -> 0 | J45: =IF(J7=1,IF(J5=Inputs_Master!$C$10,-(Inputs_Master!$C$70+Inputs_Master!$C$28*(Inputs_Master!$C$69-Inputs_Master!$C$10)/Inputs_Master!$C$69)*(1-Inputs_Master!$C$71-Inputs_Master!$C$72),0),0) -> 0 | ... AJ45: =IF(AJ7=1,IF(AJ5=Inputs_Master!$C$10,-(Inputs_Master!$C$70+Inputs_Master!$C$28*(Inputs_Master!$C$69-Inputs_Master!$C$10)/Inputs_Master!$C$69)*(1-Inputs_Master!$C$71-Inputs_Master!$C$72),0),0) -> 972
B47: TOTAL P3 CASH FLOWS TO GOA
B48: Annual Cash Flow | C48: =IF(C7=1,C34+C38+C39+C42+C45,0) -> 1.2101768 | D48: =IF(D7=1,D34+D38+D39+D42+D45,0) -> 1.1901768 | E48: =IF(E7=1,E34+E38+E39+E42+E45,0) -> 1.1901768 | F48: =IF(F7=1,F34+F38+F39+F42+F45,0) -> #N/A | G48: =IF(G7=1,G34+G38+G39+G42+G45,0) -> #N/A | H48: =IF(H7=1,H34+H38+H39+H42+H45,0) -> #N/A | I48: =IF(I7=1,I34+I38+I39+I42+I45,0) -> #N/A | J48: =IF(J7=1,J34+J38+J39+J42+J45,0) -> #N/A | ... AJ48: =IF(AJ7=1,AJ34+AJ38+AJ39+AJ42+AJ45,0) -> #N/A
B49: Discount Factor | C49: =IF(C7=1,1/POWER(1+Inputs_Master!$C$16,C5),0) -> #N/A | D49: =IF(D7=1,1/POWER(1+Inputs_Master!$C$16,D5),0) -> #N/A | E49: =IF(E7=1,1/POWER(1+Inputs_Master!$C$16,E5),0) -> #N/A | F49: =IF(F7=1,1/POWER(1+Inputs_Master!$C$16,F5),0) -> #N/A | G49: =IF(G7=1,1/POWER(1+Inputs_Master!$C$16,G5),0) -> #N/A | H49: =IF(H7=1,1/POWER(1+Inputs_Master!$C$16,H5),0) -> #N/A | I49: =IF(I7=1,1/POWER(1+Inputs_Master!$C$16,I5),0) -> #N/A | J49: =IF(J7=1,1/POWER(1+Inputs_Master!$C$16,J5),0) -> #N/A | ... AJ49: =IF(AJ7=1,1/POWER(1+Inputs_Master!$C$16,AJ5),0) -> #N/A
B50: Present Value | C50: =IF(C7=1,C48*C49,0) -> #N/A | D50: =IF(D7=1,D48*D49,0) -> #N/A | E50: =IF(E7=1,E48*E49,0) -> #N/A | F50: =IF(F7=1,F48*F49,0) -> #N/A | G50: =IF(G7=1,G48*G49,0) -> #N/A | H50: =IF(H7=1,H48*H49,0) -> #N/A | I50: =IF(I7=1,I48*I49,0) -> #N/A | J50: =IF(J7=1,J48*J49,0) -> #N/A | ... AJ50: =IF(AJ7=1,AJ48*AJ49,0) -> #N/A
B52: P3 NET PRESENT VALUE | C52: =SUM(C50:AJ50) -> #N/A
B54: BANKABILITY METRICS
...

Sheet VfM_Comparison
B2: VALUE FOR MONEY — MULTI-SCENARIO COMPARISON
B3: Comparing P3 against DBB, DB, and CM delivery methods
B5: Active PSC Comparator: | C5: =Inputs_Master!C11 -> 2025 | D5: (VfM metrics on Dashboard use this comparator)
B8: Cost Component | C8: PSC: DBB | D8: PSC: DB | E8: PSC: CM | F8: P3 (DBFM) | G8: Active VfM ($M) | H8: Active VfM (%)
B9: Base Capital Cost (PV) | C9: =Calc_PSC!C56*Delivery_Params!C7/Delivery_Params!$F$7 -> #N/A | D9: =Calc_PSC!C56*Delivery_Params!D7/Delivery_Params!$F$7 -> #N/A | E9: =Calc_PSC!C56*Delivery_Params!E7/Delivery_Params!$F$7 -> #N/A | F9: =SUMPRODUCT(Calc_P3!C12:AJ12,Calc_P3!C63:AJ63) -> #NUM!
B10: + Contingency (PV) | C10: =C9*Delivery_Params!C8 -> #N/A | D10: =D9*Delivery_Params!D8 -> #N/A | E10: =E9*Delivery_Params!E8 -> #N/A | F10: —
B11: + Professional Fees (PV) | C11: =C9*Delivery_Params!C9 -> #N/A | D11: =D9*Delivery_Params!D9 -> #N/A | E11: =E9*Delivery_Params!E9 -> #N/A | F11: —
B12: + CM Fee (PV) | C12: =C9*Delivery_Params!C10 -> #N/A | D12: =D9*Delivery_Params!D10 -> #N/A | E12: =E9*Delivery_Params!E10 -> #N/A | F12: —
B13: Total Capital Cost (PV) | C13: =SUM(C9:C12) -> #N/A | D13: =SUM(D9:D12) -> #N/A | E13: =SUM(E9:E12) -> #N/A | F13: =F9 -> #NUM!
B15: Operating Costs (PV) | C15: =Calc_PSC!C57 -> 0 | D15: =Calc_PSC!C57 -> 0 | E15: =Calc_PSC!C57*1.02 -> 0 | F15: =SUMPRODUCT(Calc_P3!C40:AJ40,Calc_P3!C63:AJ63) -> #NUM!
B16: Lifecycle Costs (PV) | C16: =Calc_PSC!C58 -> 0 | D16: =Calc_PSC!C58 -> 0 | E16: =Calc_PSC!C58 -> 0 | F16: =SUMPRODUCT(Calc_P3!C29:AJ29,Calc_P3!C63:AJ63) -> #NUM!
B18: Risk Costs (PV)
B19: Construction Risks | C19: =Risk_Register!$N$16*Delivery_Params!C14*0.75 -> 0 | D19: =Risk_Register!$N$16*Delivery_Params!D14*0.75 -> 0 | E19: =Risk_Register!$N$16*Delivery_Params!E14*0.75 -> 0 | F19: =Risk_Register!$N$18*0.75 -> 29.456875
B20: Operating Risks | C20: =Risk_Register!$N$17*Delivery_Params!C17*0.75 -> 34.300625 | D20: =Risk_Register!$N$17*Delivery_Params!D17*0.75 -> 6.860125 | E20: =Risk_Register!$N$17*Delivery_Params!E17*0.75 -> 27.4405 | F20: =Risk_Register!$N$18*0.25 -> 9.8189583
B21: Total Risk Costs (PV) | C21: =C19+C20 -> 34.300625 | D21: =D19+D20 -> 6.860125 | E21: =E19+E20 -> 27.4405 | F21: =F19+F20 -> 39.275833
B23: Competitive Neutrality (PV) | C23: =Calc_PSC!C60 -> 0 | D23: =Calc_PSC!C60*0.95 -> 0 | E23: =Calc_PSC!C60*0.98 -> 0 | F23: —
B25: Residual Value Credit (PV) | C25: =Calc_PSC!C61 -> 0 | D25: =Calc_PSC!C61 -> 0 | E25: =Calc_PSC!C61 -> 0 | F25: =SUMPRODUCT(Calc_P3!C54:AJ54,Calc_P3!C63:AJ63) -> #NUM!
B27: TOTAL NET PRESENT VALUE | C27: =C13+C15+C16+C21+C23+C25 -> #N/A | D27: =D13+D15+D16+D21+D23+D25 -> #N/A | E27: =E13+E15+E16+E21+E23+E25 -> #N/A | F27: =Calc_P3!C70 -> 0
B29: VALUE FOR MONEY ANALYSIS
B30: VfM ($M) = PSC - P3 | C30: =C27-$F$27 -> #N/A | D30: =D27-$F$27 -> #N/A | E30: =E27-$F$27 -> #N/A | F30: — | G30: =INDEX(C30:E30,Inputs_Master!$C$12) -> #N/A | H30: =G30/INDEX(C27:E27,Inputs_Master!$C$12) -> #N/A
B32: VfM Status | C32: =IF(C30>0,"✓ POSITIVE","✗ NEGATIVE") -> #N/A | D32: =IF(D30>0,"✓ POSITIVE","✗ NEGATIVE") -> #N/A | E32: =IF(E30>0,"✓ POSITIVE","✗ NEGATIVE") -> #N/A
B34: RISK TRANSFER ANALYSIS
B35: Risk Transfer Value ($M) | C35: =C21-$F$21 -> -4.9752083 | D35: =D21-$F$21 -> -32.415708 | E35: =E21-$F$21 -> -11.835333 | F35: —
B36: Risk Transfer as % of VfM | C36: =IF(C30<>0,C35/C30,0) -> #N/A | D36: =IF(D30<>0,D35/D30,0) -> #N/A | E36: =IF(E30<>0,E35/E30,0) -> #N/A
B39: INTERPRETATION
B40: =CONCATENATE("P3 delivery provides positive Value for Money against all conventional delivery methods analyzed. ","The strongest case for P3 is versus ",IF(C30>=D30,IF(C30>=E30,"DBB","CM"),IF(D30>=E30,"DB","CM"))," with VfM of $",ROUND(MAX(C30:E30),1),"M (",ROUND(MAX(C30:E30)/MAX(C27:E27)*100,1),"%). ","Risk transfer accounts for the majority of VfM across all scenarios.") -> #N/A

Sheet Sensitivity
